Workbook

Sheet Summary
A1: Retail Sales Analysis: Summary
A2: All figures are live formulas over the Clean_Data sheet.
A4: KPI | B4: Value
A5: Total Sales | B5: =SUM(Clean_Data!$J$2:$J$9001) -> 4716265.2
A6: Total Profit | B6: =SUM(Clean_Data!$K$2:$K$9001) -> 326333.61
A7: Profit Margin | B7: =B6/B5 -> 0.069193227
A8: Orders | B8: =COUNTA(Clean_Data!$A$2:$A$9001) -> 9000
A9: Average Order Value | B9: =B5/B8 -> 524.02947
A10: Average Discount | B10: =AVERAGE(Clean_Data!$I$2:$I$9001) -> 0.10181111
A11: Loss-Making Orders % | B11: =COUNTIF(Clean_Data!$K$2:$K$9001,"<0")/B8 -> 0.20277778
A14: By Category
A15: Category | B15: Sales | C15: Profit | D15: Margin
A16: Furniture | B16: =SUMIFS(Clean_Data!$J$2:$J$9001,Clean_Data!$F$2:$F$9001,A16) -> 1614729.7 | C16: =SUMIFS(Clean_Data!$K$2:$K$9001,Clean_Data!$F$2:$F$9001,A16) -> -64060.86 | D16: =IF(B16=0,0,C16/B16) -> -0.039672807
A17: Office Supplies | B17: =SUMIFS(Clean_Data!$J$2:$J$9001,Clean_Data!$F$2:$F$9001,A17) -> 846623.11 | C17: =SUMIFS(Clean_Data!$K$2:$K$9001,Clean_Data!$F$2:$F$9001,A17) -> 110677.2 | D17: =IF(B17=0,0,C17/B17) -> 0.13072783
A18: Technology | B18: =SUMIFS(Clean_Data!$J$2:$J$9001,Clean_Data!$F$2:$F$9001,A18) -> 2254912.5 | C18: =SUMIFS(Clean_Data!$K$2:$K$9001,Clean_Data!$F$2:$F$9001,A18) -> 279717.27 | D18: =IF(B18=0,0,C18/B18) -> 0.12404795
A19: Total | B19: =SUM(B16:B18) -> 4716265.2 | C19: =SUM(C16:C18) -> 326333.61 | D19: =IF(B19=0,0,C19/B19) -> 0.069193227
A22: By Sub-Category
A23: Sub-Category | B23: Sales | C23: Profit | D23: Margin
A24: Tables | B24: =SUMIFS(Clean_Data!$J$2:$J$9001,Clean_Data!$G$2:$G$9001,A24) -> 624760.46 | C24: =SUMIFS(Clean_Data!$K$2:$K$9001,Clean_Data!$G$2:$G$9001,A24) -> -71281.26 | D24: =IF(B24=0,0,C24/B24) -> -0.11409374
A25: Bookcases | B25: =SUMIFS(Clean_Data!$J$2:$J$9001,Clean_Data!$G$2:$G$9001,A25) -> 365341.24 | C25: =SUMIFS(Clean_Data!$K$2:$K$9001,Clean_Data!$G$2:$G$9001,A25) -> -22002.96 | D25: =IF(B25=0,0,C25/B25) -> -0.060225777
A26: Machines | B26: =SUMIFS(Clean_Data!$J$2:$J$9001,Clean_Data!$G$2:$G$9001,A26) -> 417627.48 | C26: =SUMIFS(Clean_Data!$K$2:$K$9001,Clean_Data!$G$2:$G$9001,A26) -> -7633.42 | D26: =IF(B26=0,0,C26/B26) -> -0.01827806
A27: Chairs | B27: =SUMIFS(Clean_Data!$J$2:$J$9001,Clean_Data!$G$2:$G$9001,A27) -> 490928.65 | C27: =SUMIFS(Clean_Data!$K$2:$K$9001,Clean_Data!$G$2:$G$9001,A27) -> 10195.57 | D27: =IF(B27=0,0,C27/B27) -> 0.020767926
A28: Storage | B28: =SUMIFS(Clean_Data!$J$2:$J$9001,Clean_Data!$G$2:$G$9001,A28) -> 304799.22 | C28: =SUMIFS(Clean_Data!$K$2:$K$9001,Clean_Data!$G$2:$G$9001,A28) -> 12912.11 | D28: =IF(B28=0,0,C28/B28) -> 0.042362674
A29: Furnishings | B29: =SUMIFS(Clean_Data!$J$2:$J$9001,Clean_Data!$G$2:$G$9001,A29) -> 133699.34 | C29: =SUMIFS(Clean_Data!$K$2:$K$9001,Clean_Data!$G$2:$G$9001,A29) -> 19027.79 | D29: =IF(B29=0,0,C29/B29) -> 0.14231776
A30: Binders | B30: =SUMIFS(Clean_Data!$J$2:$J$9001,Clean_Data!$G$2:$G$9001,A30) -> 117595.6 | C30: =SUMIFS(Clean_Data!$K$2:$K$9001,Clean_Data!$G$2:$G$9001,A30) -> 25978.21 | D30: =IF(B30=0,0,C30/B30) -> 0.22091141
A31: Paper | B31: =SUMIFS(Clean_Data!$J$2:$J$9001,Clean_Data!$G$2:$G$9001,A31) -> 101263.06 | C31: =SUMIFS(Clean_Data!$K$2:$K$9001,Clean_Data!$G$2:$G$9001,A31) -> 31065.17 | D31: =IF(B31=0,0,C31/B31) -> 0.30677692
A32: Accessories | B32: =SUMIFS(Clean_Data!$J$2:$J$9001,Clean_Data!$G$2:$G$9001,A32) -> 162970.6 | C32: =SUMIFS(Clean_Data!$K$2:$K$9001,Clean_Data!$G$2:$G$9001,A32) -> 35776.32 | D32: =IF(B32=0,0,C32/B32) -> 0.21952622
A33: Appliances | B33: =SUMIFS(Clean_Data!$J$2:$J$9001,Clean_Data!$G$2:$G$9001,A33) -> 322965.23 | C33: =SUMIFS(Clean_Data!$K$2:$K$9001,Clean_Data!$G$2:$G$9001,A33) -> 40721.71 | D33: =IF(B33=0,0,C33/B33) -> 0.12608698
A34: Phones | B34: =SUMIFS(Clean_Data!$J$2:$J$9001,Clean_Data!$G$2:$G$9001,A34) -> 855213.16 | C34: =SUMIFS(Clean_Data!$K$2:$K$9001,Clean_Data!$G$2:$G$9001,A34) -> 86362.04 | D34: =IF(B34=0,0,C34/B34) -> 0.10098306
A35: Copiers | B35: =SUMIFS(Clean_Data!$J$2:$J$9001,Clean_Data!$G$2:$G$9001,A35) -> 819101.21 | C35: =SUMIFS(Clean_Data!$K$2:$K$9001,Clean_Data!$G$2:$G$9001,A35) -> 165212.33 | D35: =IF(B35=0,0,C35/B35) -> 0.20169953
A36: Total | B36: =SUM(B24:B35) -> 4716265.2 | C36: =SUM(C24:C35) -> 326333.61 | D36: =IF(B36=0,0,C36/B36) -> 0.069193227
A39: By Region
A40: Region | B40: Sales | C40: Profit | D40: Margin
A41: Central | B41: =SUMIFS(Clean_Data!$J$2:$J$9001,Clean_Data!$E$2:$E$9001,A41) -> 976909.49 | C41: =SUMIFS(Clean_Data!$K$2:$K$9001,Clean_Data!$E$2:$E$9001,A41) -> 71569.68 | D41: =IF(B41=0,0,C41/B41) -> 0.073261321
A42: East | B42: =SUMIFS(Clean_Data!$J$2:$J$9001,Clean_Data!$E$2:$E$9001,A42) -> 1318198 | C42: =SUMIFS(Clean_Data!$K$2:$K$9001,Clean_Data!$E$2:$E$9001,A42) -> 82835.28 | D42: =IF(B42=0,0,C42/B42) -> 0.062839786
A43: South | B43: =SUMIFS(Clean_Data!$J$2:$J$9001,Clean_Data!$E$2:$E$9001,A43) -> 764096.2 | C43: =SUMIFS(Clean_Data!$K$2:$K$9001,Clean_Data!$E$2:$E$9001,A43) -> 54008.84 | D43: =IF(B43=0,0,C43/B43) -> 0.070683299
A44: West | B44: =SUMIFS(Clean_Data!$J$2:$J$9001,Clean_Data!$E$2:$E$9001,A44) -> 1657061.6 | C44: =SUMIFS(Clean_Data!$K$2:$K$9001,Clean_Data!$E$2:$E$9001,A44) -> 117919.81 | D44: =IF(B44=0,0,C44/B44) -> 0.071161997
A45: Total | B45: =SUM(B41:B44) -> 4716265.2 | C45: =SUM(C41:C44) -> 326333.61 | D45: =IF(B45=0,0,C45/B45) -> 0.069193227
A48: By Segment
A49: Segment | B49: Sales | C49: Profit | D49: Margin
...

Sheet Clean_Data
A1: Order ID | B1: Order Date | C1: Ship Mode | D1: Segment | E1: Region | F1: Category | G1: Sub-Category | H1: Quantity | I1: Discount | J1: Sales | K1: Profit | L1: Year | M1: Profit Margin
A2: ORD-2022-01264 | B2: 44844 | C2: Standard Class | D2: Corporate | E2: East | F2: Furniture | G2: Chairs | H2: 4 | I2: 0 | J2: 1387 | K2: 191.18 | L2: =YEAR(B2) -> 2022 | M2: =IF(J2>0,K2/J2,0) -> 0.13783706
A3: ORD-2022-00094 | B3: 44587 | C3: Same Day | D3: Consumer | E3: East | F3: Technology | G3: Machines | H3: 6 | I3: 0.15 | J3: 3542.41 | K3: -130.16 | L3: =YEAR(B3) -> 2022 | M3: =IF(J3>0,K3/J3,0) -> -0.036743347
A4: ORD-2023-03318 | B4: 45206 | C4: Standard Class | D4: Consumer | E4: East | F4: Office Supplies | G4: Binders | H4: 2 | I4: 0.15 | J4: 44.03 | K4: 6.91 | L4: =YEAR(B4) -> 2023 | M4: =IF(J4>0,K4/J4,0) -> 0.15693845
A5: ORD-2024-06022 | B5: 45617 | C5: Standard Class | D5: Consumer | E5: West | F5: Office Supplies | G5: Storage | H5: 5 | I5: 0.2 | J5: 409.22 | K5: -12.17 | L5: =YEAR(B5) -> 2024 | M5: =IF(J5>0,K5/J5,0) -> -0.029739504
A6: ORD-2024-05695 | B6: 45578 | C6: Standard Class | D6: Corporate | E6: Central | F6: Office Supplies | G6: Paper | H6: 8 | I6: 0.05 | J6: 139.53 | K6: 48.9 | L6: =YEAR(B6) -> 2024 | M6: =IF(J6>0,K6/J6,0) -> 0.35046227
A7: ORD-2024-04662 | B7: 45420 | C7: Standard Class | D7: Home Office | E7: East | F7: Office Supplies | G7: Binders | H7: 4 | I7: 0 | J7: 94.35 | K7: 29.81 | L7: =YEAR(B7) -> 2024 | M7: =IF(J7>0,K7/J7,0) -> 0.31595125
A8: ORD-2023-02684 | B8: 45096 | C8: Standard Class | D8: Consumer | E8: Central | F8: Office Supplies | G8: Appliances | H8: 3 | I8: 0 | J8: 344.11 | K8: 60.21 | L8: =YEAR(B8) -> 2023 | M8: =IF(J8>0,K8/J8,0) -> 0.17497312
A9: ORD-2022-00829 | B9: 44763 | C9: Same Day | D9: Consumer | E9: Central | F9: Furniture | G9: Furnishings | H9: 5 | I9: 0.2 | J9: 206.17 | K9: -16.2 | L9: =YEAR(B9) -> 2022 | M9: =IF(J9>0,K9/J9,0) -> -0.078575932
A10: ORD-2025-07089 | B10: 45781 | C10: Standard Class | D10: Consumer | E10: West | F10: Office Supplies | G10: Paper | H10: 1 | I10: 0.1 | J10: 14.08 | K10: 5.48 | L10: =YEAR(B10) -> 2025 | M10: =IF(J10>0,K10/J10,0) -> 0.38920455
A11: ORD-2023-01920 | B11: 44944 | C11: Standard Class | D11: Corporate | E11: South | F11: Technology | G11: Phones | H11: 3 | I11: 0 | J11: 1247.38 | K11: 203.68 | L11: =YEAR(B11) -> 2023 | M11: =IF(J11>0,K11/J11,0) -> 0.16328625
A12: ORD-2023-03543 | B12: 45241 | C12: First Class | D12: Corporate | E12: West | F12: Technology | G12: Accessories | H12: 4 | I12: 0.15 | J12: 156.53 | K12: 27.03 | L12: =YEAR(B12) -> 2023 | M12: =IF(J12>0,K12/J12,0) -> 0.17268255
A13: ORD-2024-04392 | B13: 45372 | C13: Standard Class | D13: Corporate | E13: South | F13: Office Supplies | G13: Storage | H13: 4 | I13: 0.4 | J13: 203.16 | K13: -44.77 | L13: =YEAR(B13) -> 2024 | M13: =IF(J13>0,K13/J13,0) -> -0.22036818
... A9001: ORD-2025-07271 | B9001: 45807 | C9001: Standard Class | D9001: Consumer | E9001: South | F9001: Office Supplies | G9001: Appliances | H9001: 1 | I9001: 0 | J9001: 106.68 | K9001: 18.64 | L9001: =YEAR(B9001) -> 2025 | M9001: =IF(J9001>0,K9001/J9001,0) -> 0.17472816

Sheet Model_Results
A1: Regression Model Results (from Python notebook)
A2: Blue values are inputs copied from reports/metrics.json produced by notebooks/capstone_sales_analysis.ipynb. Target: Sales (log1p-transformed), 80/20 train-test split, random_state=42.
A4: Model | B4: R2 (test, USD) | C4: MAE (USD) | D4: RMSE (USD) | E4: CV R2 (log, 5-fold)
A5: Linear Regression | B5: 0.899 | C5: 86.589 | D5: 252 | E5: 0.979
A6: Random Forest | B6: 0.967 | C6: 61.25 | D6: 142.826 | E6: 0.988
A7: Gradient Boosting | B7: 0.978 | C7: 52.196 | D7: 117.12 | E7: 0.991
A9: Best model (highest R2) | B9: =INDEX(A5:A7,MATCH(MAX(B5:B7),B5:B7,0)) -> Gradient Boosting
A11: Feature importance (Gradient Boosting)
A12: Feature | B12: Importance
A13: Sub-Category | B13: 0.5169
A14: Category | B14: 0.3266
A15: Quantity | B15: 0.14
A16: Discount | B16: 0.0132
A17: Region | B17: 0.0023
A18: Segment | B18: 0.0007
A19: Month | B19: 0.0001
A20: DayOfWeek | B20: 0.0001
A21: Ship Mode | B21: 0.0001
A22: Year | B22: 0

Sheet Notes
A1: Notes and Assumptions
A3: Project | B3: Week 4 Capstone: Retail Sales Analysis and Prediction
A4: Data source | B4: Synthetic retail dataset generated by src/generate_data.py (seed 42). The capstone brief supplied no dataset.
A5: Cleaning | B5: 45 duplicate rows removed; missing Segment and Ship Mode filled with the mode.
A6: Rows | B6: 9,000 cleaned order lines, 2022-01-01 to 2025-12-31.
A7: Formulas | B7: Year, Profit Margin and every Summary table are formulas. Model_Results blue cells are pasted inputs from Python.
A8: Re-use | B8: To analyse real data, paste it into Clean_Data (same columns A:K); the Summary sheet recalculates. Update the row range if the row count changes.
